在try-catch-finally中
1. 正常执行没问题
2. 如果try中有异常，没有被catch，则finally直接执行，最后会抛出
3. 如果catch了异常，finally在catch代码之后执行
4. 如果catch中有异常，finally会执行，最后抛出catch中触发的异常
5. 如果finally也有异常，则中断当前finally的执行，然后抛出异常

